<sdf version='1.5'>
  <model name='iris_dronecourse'>

    <include>
      <uri>model://iris</uri>

    </include>

	<include>
      <uri>model://sonar</uri>
    </include>
    <joint name="sonar_joint" type="revolute">
	  <parent>iris::base_link</parent>
      <child>sonar_model::link</child>
      <pose frame=''>0 0 0 0 0 0</pose>
      <axis>
        <xyz>0 0 1</xyz>
        <limit>
          <upper>0</upper>
          <lower>0</lower>
        </limit>
      </axis>
    </joint>

    <link name='target_cam'>
      <pose frame=''> 0 0 0 0 0 0.0 </pose>
      <inertial>
        <mass>1e-9</mass>
        <inertia>
          <ixx>1e-9</ixx>
          <ixy>0</ixy>
          <ixz>0</ixz>
          <iyy>1e-9</iyy>
          <iyz>0</iyz>
          <izz>1e-9</izz>
        </inertia>
      </inertial>
      <sensor name="camera" type="camera">
        <!-- To Change pose, change pose of the link, not of the sensor-->
        <pose frame=''> 0 0 0 0 0 0 </pose>
        <always_on>true</always_on>
        <update_rate>2</update_rate>
        <visualize>true</visualize>
        <camera>
          <horizontal_fov>1.0</horizontal_fov>
          <image>
            <width>640</width>
            <height>480</height>
          </image>
          <clip>
            <near>0.1</near>
            <far>1000</far>
          </clip>
        </camera>
      </sensor>
    </link>
    <joint name='gimbal_joint' type="ball">
      <parent>iris::base_link</parent>
      <child>target_cam</child>
      <pose frame=''>0 0 0 0 0 0</pose>
      <parent>chassis</parent>
    </joint>
    <plugin name='TargetCameraPlugin' filename='libgazebo_target_camera_plugin.so'>
      <target_link>truck::target_platform</target_link>
      <target_link>platform::box</target_link>
      <gimbal_joint>gimbal_joint</gimbal_joint>
      <noise_xy>4</noise_xy>
      <noise_z>0.1</noise_z>
      <mavlink_addr>INADDR_ANY</mavlink_addr>
      <mavlink_udp_port>14580</mavlink_udp_port>
    </plugin>
  </model>
</sdf>
